2023-06-21 13:16:02,435 -  nornir.core -     INFO -        run() - Running task 'netmiko_send_command' with args {'command_string': 'show ip int brief'} on 6 hosts
2023-06-21 13:16:13,083 -  nornir.core -     INFO -        run() - Running task 'netmiko_send_command' with args {'command_string': 'show ip int brief'} on 2 hosts
2023-06-21 13:23:00,704 -  nornir.core -     INFO -        run() - Running task 'netmiko_send_command' with args {'command_string': 'show ip int brief'} on 2 hosts
2023-06-21 13:25:42,892 -  nornir.core -     INFO -        run() - Running task 'netmiko_send_command' with args {'command_string': 'show ip int brief'} on 2 hosts
2023-06-21 13:27:18,995 -  nornir.core -     INFO -        run() - Running task 'netmiko_send_command' with args {'command_string': 'show ip int brief'} on 2 hosts
2023-06-21 13:27:21,492 - nornir.core.task -    ERROR -      start() - Host 'cisco3': task 'netmiko_send_command' failed with traceback:
Traceback (most recent call last):
  File "/home/delbrugge/VENV/py3_venv/lib/python3.9/site-packages/netmiko/base_connection.py", line 1104, in establish_connection
    self.remote_conn_pre.connect(**ssh_connect_params)
  File "/home/delbrugge/VENV/py3_venv/lib/python3.9/site-packages/paramiko/client.py", line 459, in connect
    self._auth(
  File "/home/delbrugge/VENV/py3_venv/lib/python3.9/site-packages/paramiko/client.py", line 790, in _auth
    raise saved_exception
  File "/home/delbrugge/VENV/py3_venv/lib/python3.9/site-packages/paramiko/client.py", line 777, in _auth
    self._transport.auth_password(username, password)
  File "/home/delbrugge/VENV/py3_venv/lib/python3.9/site-packages/paramiko/transport.py", line 1569, in auth_password
    return self.auth_handler.wait_for_response(my_event)
  File "/home/delbrugge/VENV/py3_venv/lib/python3.9/site-packages/paramiko/auth_handler.py", line 259, in wait_for_response
    raise e
paramiko.ssh_exception.AuthenticationException: Authentication failed.

During handling of the above exception, another exception occurred:

Traceback (most recent call last):
  File "/home/delbrugge/VENV/py3_venv/lib/python3.9/site-packages/nornir/core/task.py", line 99, in start
    r = self.task(self, **self.params)
  File "/home/delbrugge/VENV/py3_venv/lib/python3.9/site-packages/nornir_netmiko/tasks/netmiko_send_command.py", line 26, in netmiko_send_command
    net_connect = task.host.get_connection(CONNECTION_NAME, task.nornir.config)
  File "/home/delbrugge/VENV/py3_venv/lib/python3.9/site-packages/nornir/core/inventory.py", line 494, in get_connection
    self.open_connection(
  File "/home/delbrugge/VENV/py3_venv/lib/python3.9/site-packages/nornir/core/inventory.py", line 546, in open_connection
    conn_obj.open(
  File "/home/delbrugge/VENV/py3_venv/lib/python3.9/site-packages/nornir_netmiko/connections/netmiko.py", line 59, in open
    connection = ConnectHandler(**parameters)
  File "/home/delbrugge/VENV/py3_venv/lib/python3.9/site-packages/netmiko/ssh_dispatcher.py", line 388, in ConnectHandler
    return ConnectionClass(*args, **kwargs)
  File "/home/delbrugge/VENV/py3_venv/lib/python3.9/site-packages/netmiko/base_connection.py", line 462, in __init__
    self._open()
  File "/home/delbrugge/VENV/py3_venv/lib/python3.9/site-packages/netmiko/base_connection.py", line 467, in _open
    self.establish_connection()
  File "/home/delbrugge/VENV/py3_venv/lib/python3.9/site-packages/netmiko/base_connection.py", line 1141, in establish_connection
    raise NetmikoAuthenticationException(msg)
netmiko.exceptions.NetmikoAuthenticationException: Authentication to device failed.

Common causes of this problem are:
1. Invalid username and password
2. Incorrect SSH-key file
3. Connecting to the wrong device

Device settings: cisco_ios cisco3.lasthop.io:22


Authentication failed.

2023-06-21 13:51:57,324 -  nornir.core -     INFO -        run() - Running task 'netmiko_send_command' with args {'command_string': 'show ip int brief'} on 2 hosts
2023-06-21 13:52:21,987 -  nornir.core -     INFO -        run() - Running task 'netmiko_send_command' with args {'command_string': 'show ip int brief'} on 2 hosts
2023-06-21 13:52:24,495 - nornir.core.task -    ERROR -      start() - Host 'cisco3': task 'netmiko_send_command' failed with traceback:
Traceback (most recent call last):
  File "/home/delbrugge/VENV/py3_venv/lib/python3.9/site-packages/netmiko/base_connection.py", line 1104, in establish_connection
    self.remote_conn_pre.connect(**ssh_connect_params)
  File "/home/delbrugge/VENV/py3_venv/lib/python3.9/site-packages/paramiko/client.py", line 459, in connect
    self._auth(
  File "/home/delbrugge/VENV/py3_venv/lib/python3.9/site-packages/paramiko/client.py", line 790, in _auth
    raise saved_exception
  File "/home/delbrugge/VENV/py3_venv/lib/python3.9/site-packages/paramiko/client.py", line 777, in _auth
    self._transport.auth_password(username, password)
  File "/home/delbrugge/VENV/py3_venv/lib/python3.9/site-packages/paramiko/transport.py", line 1569, in auth_password
    return self.auth_handler.wait_for_response(my_event)
  File "/home/delbrugge/VENV/py3_venv/lib/python3.9/site-packages/paramiko/auth_handler.py", line 259, in wait_for_response
    raise e
paramiko.ssh_exception.AuthenticationException: Authentication failed.

During handling of the above exception, another exception occurred:

Traceback (most recent call last):
  File "/home/delbrugge/VENV/py3_venv/lib/python3.9/site-packages/nornir/core/task.py", line 99, in start
    r = self.task(self, **self.params)
  File "/home/delbrugge/VENV/py3_venv/lib/python3.9/site-packages/nornir_netmiko/tasks/netmiko_send_command.py", line 26, in netmiko_send_command
    net_connect = task.host.get_connection(CONNECTION_NAME, task.nornir.config)
  File "/home/delbrugge/VENV/py3_venv/lib/python3.9/site-packages/nornir/core/inventory.py", line 494, in get_connection
    self.open_connection(
  File "/home/delbrugge/VENV/py3_venv/lib/python3.9/site-packages/nornir/core/inventory.py", line 546, in open_connection
    conn_obj.open(
  File "/home/delbrugge/VENV/py3_venv/lib/python3.9/site-packages/nornir_netmiko/connections/netmiko.py", line 59, in open
    connection = ConnectHandler(**parameters)
  File "/home/delbrugge/VENV/py3_venv/lib/python3.9/site-packages/netmiko/ssh_dispatcher.py", line 388, in ConnectHandler
    return ConnectionClass(*args, **kwargs)
  File "/home/delbrugge/VENV/py3_venv/lib/python3.9/site-packages/netmiko/base_connection.py", line 462, in __init__
    self._open()
  File "/home/delbrugge/VENV/py3_venv/lib/python3.9/site-packages/netmiko/base_connection.py", line 467, in _open
    self.establish_connection()
  File "/home/delbrugge/VENV/py3_venv/lib/python3.9/site-packages/netmiko/base_connection.py", line 1141, in establish_connection
    raise NetmikoAuthenticationException(msg)
netmiko.exceptions.NetmikoAuthenticationException: Authentication to device failed.

Common causes of this problem are:
1. Invalid username and password
2. Incorrect SSH-key file
3. Connecting to the wrong device

Device settings: cisco_ios cisco3.lasthop.io:22


Authentication failed.

2023-06-21 13:53:11,710 -  nornir.core -     INFO -        run() - Running task 'netmiko_send_command' with args {'command_string': 'show ip int brief'} on 2 hosts
2023-06-21 13:53:14,410 - nornir.core.task -    ERROR -      start() - Host 'cisco3': task 'netmiko_send_command' failed with traceback:
Traceback (most recent call last):
  File "/home/delbrugge/VENV/py3_venv/lib/python3.9/site-packages/netmiko/base_connection.py", line 1104, in establish_connection
    self.remote_conn_pre.connect(**ssh_connect_params)
  File "/home/delbrugge/VENV/py3_venv/lib/python3.9/site-packages/paramiko/client.py", line 459, in connect
    self._auth(
  File "/home/delbrugge/VENV/py3_venv/lib/python3.9/site-packages/paramiko/client.py", line 790, in _auth
    raise saved_exception
  File "/home/delbrugge/VENV/py3_venv/lib/python3.9/site-packages/paramiko/client.py", line 777, in _auth
    self._transport.auth_password(username, password)
  File "/home/delbrugge/VENV/py3_venv/lib/python3.9/site-packages/paramiko/transport.py", line 1569, in auth_password
    return self.auth_handler.wait_for_response(my_event)
  File "/home/delbrugge/VENV/py3_venv/lib/python3.9/site-packages/paramiko/auth_handler.py", line 259, in wait_for_response
    raise e
paramiko.ssh_exception.AuthenticationException: Authentication failed.

During handling of the above exception, another exception occurred:

Traceback (most recent call last):
  File "/home/delbrugge/VENV/py3_venv/lib/python3.9/site-packages/nornir/core/task.py", line 99, in start
    r = self.task(self, **self.params)
  File "/home/delbrugge/VENV/py3_venv/lib/python3.9/site-packages/nornir_netmiko/tasks/netmiko_send_command.py", line 26, in netmiko_send_command
    net_connect = task.host.get_connection(CONNECTION_NAME, task.nornir.config)
  File "/home/delbrugge/VENV/py3_venv/lib/python3.9/site-packages/nornir/core/inventory.py", line 494, in get_connection
    self.open_connection(
  File "/home/delbrugge/VENV/py3_venv/lib/python3.9/site-packages/nornir/core/inventory.py", line 546, in open_connection
    conn_obj.open(
  File "/home/delbrugge/VENV/py3_venv/lib/python3.9/site-packages/nornir_netmiko/connections/netmiko.py", line 59, in open
    connection = ConnectHandler(**parameters)
  File "/home/delbrugge/VENV/py3_venv/lib/python3.9/site-packages/netmiko/ssh_dispatcher.py", line 388, in ConnectHandler
    return ConnectionClass(*args, **kwargs)
  File "/home/delbrugge/VENV/py3_venv/lib/python3.9/site-packages/netmiko/base_connection.py", line 462, in __init__
    self._open()
  File "/home/delbrugge/VENV/py3_venv/lib/python3.9/site-packages/netmiko/base_connection.py", line 467, in _open
    self.establish_connection()
  File "/home/delbrugge/VENV/py3_venv/lib/python3.9/site-packages/netmiko/base_connection.py", line 1141, in establish_connection
    raise NetmikoAuthenticationException(msg)
netmiko.exceptions.NetmikoAuthenticationException: Authentication to device failed.

Common causes of this problem are:
1. Invalid username and password
2. Incorrect SSH-key file
3. Connecting to the wrong device

Device settings: cisco_ios cisco3.lasthop.io:22


Authentication failed.

